<?xml version="1.0" encoding="UTF-8"?>
<testng-results skipped="0" failed="3" total="3" passed="0">
  <reporter-output>
  </reporter-output>
  <suite name="Default suite" duration-ms="42077" started-at="2019-07-09T10:01:00Z" finished-at="2019-07-09T10:01:42Z">
    <groups>
    </groups>
    <test name="Default test" duration-ms="42077" started-at="2019-07-09T10:01:00Z" finished-at="2019-07-09T10:01:42Z">
      <class name="Rough.Newmultiplelogin">
        <test-method status="FAIL" signature="DataDrivenFrameEx(java.lang.String, java.lang.String)[pri:0, instance:Rough.Newmultiplelogin@7cdbc5d3]" name="DataDrivenFrameEx" duration-ms="14597" started-at="2019-07-09T15:31:01Z" data-provider="getData" finished-at="2019-07-09T15:31:15Z">
          <params>
            <param index="0">
              <value>
                <![CDATA[admin]]>
              </value>
            </param>
            <param index="1">
              <value>
                <![CDATA[admin123]]>
              </value>
            </param>
          </params>
          <exception class="java.lang.AssertionError">
            <message>
              <![CDATA[expected [https://opensource-demo.orangehrmlive.com/index.php/admin/viewSystemUsers] but found [https://opensource-demo.orangehrmlive.com/index.php/dashboard]]]>
            </message>
            <full-stacktrace>
              <![CDATA[java.lang.AssertionError: expected [https://opensource-demo.orangehrmlive.com/index.php/admin/viewSystemUsers] but found [https://opensource-demo.orangehrmlive.com/index.php/dashboard]
	at org.testng.Assert.fail(Assert.java:94)
	at org.testng.Assert.failNotEquals(Assert.java:496)
	at org.testng.Assert.assertEquals(Assert.java:125)
	at org.testng.Assert.assertEquals(Assert.java:178)
	at org.testng.Assert.assertEquals(Assert.java:188)
	at Rough.Newmultiplelogin.DataDrivenFrameEx(Newmultiplelogin.java:46)
	at sun.reflect.NativeMethodAccessorImpl.invoke0(Native Method)
	at sun.reflect.NativeMethodAccessorImpl.invoke(Unknown Source)
	at sun.reflect.DelegatingMethodAccessorImpl.invoke(Unknown Source)
	at java.lang.reflect.Method.invoke(Unknown Source)
	at org.testng.internal.MethodInvocationHelper.invokeMethod(MethodInvocationHelper.java:85)
	at org.testng.internal.Invoker.invokeMethod(Invoker.java:639)
	at org.testng.internal.Invoker.invokeTestMethod(Invoker.java:816)
	at org.testng.internal.Invoker.invokeTestMethods(Invoker.java:1124)
	at org.testng.internal.TestMethodWorker.invokeTestMethods(TestMethodWorker.java:125)
	at org.testng.internal.TestMethodWorker.run(TestMethodWorker.java:108)
	at org.testng.TestRunner.privateRun(TestRunner.java:774)
	at org.testng.TestRunner.run(TestRunner.java:624)
	at org.testng.SuiteRunner.runTest(SuiteRunner.java:359)
	at org.testng.SuiteRunner.runSequentially(SuiteRunner.java:354)
	at org.testng.SuiteRunner.privateRun(SuiteRunner.java:312)
	at org.testng.SuiteRunner.run(SuiteRunner.java:261)
	at org.testng.SuiteRunnerWorker.runSuite(SuiteRunnerWorker.java:52)
	at org.testng.SuiteRunnerWorker.run(SuiteRunnerWorker.java:86)
	at org.testng.TestNG.runSuitesSequentially(TestNG.java:1215)
	at org.testng.TestNG.runSuitesLocally(TestNG.java:1140)
	at org.testng.TestNG.run(TestNG.java:1048)
	at org.testng.remote.RemoteTestNG.run(RemoteTestNG.java:112)
	at org.testng.remote.RemoteTestNG.initAndRun(RemoteTestNG.java:205)
	at org.testng.remote.RemoteTestNG.main(RemoteTestNG.java:176)
]]>
            </full-stacktrace>
          </exception> <!-- java.lang.AssertionError -->
          <reporter-output>
          </reporter-output>
        </test-method> <!-- DataDrivenFrameEx -->
        <test-method status="PASS" signature="closeapp()[pri:0, instance:Rough.Newmultiplelogin@7cdbc5d3]" name="closeapp" is-config="true" duration-ms="1003" started-at="2019-07-09T15:31:15Z" finished-at="2019-07-09T15:31:16Z">
          <reporter-output>
          </reporter-output>
        </test-method> <!-- closeapp -->
        <test-method status="FAIL" signature="DataDrivenFrameEx(java.lang.String, java.lang.String)[pri:0, instance:Rough.Newmultiplelogin@7cdbc5d3]" name="DataDrivenFrameEx" duration-ms="12215" started-at="2019-07-09T15:31:16Z" data-provider="getData" finished-at="2019-07-09T15:31:28Z">
          <params>
            <param index="0">
              <value>
                <![CDATA[daaaa]]>
              </value>
            </param>
            <param index="1">
              <value>
                <![CDATA[admin1234]]>
              </value>
            </param>
          </params>
          <exception class="java.lang.AssertionError">
            <message>
              <![CDATA[expected [https://opensource-demo.orangehrmlive.com/index.php/auth/validateCredentials] but found [https://opensource-demo.orangehrmlive.com/index.php/dashboard]]]>
            </message>
            <full-stacktrace>
              <![CDATA[java.lang.AssertionError: expected [https://opensource-demo.orangehrmlive.com/index.php/auth/validateCredentials] but found [https://opensource-demo.orangehrmlive.com/index.php/dashboard]
	at org.testng.Assert.fail(Assert.java:94)
	at org.testng.Assert.failNotEquals(Assert.java:496)
	at org.testng.Assert.assertEquals(Assert.java:125)
	at org.testng.Assert.assertEquals(Assert.java:178)
	at org.testng.Assert.assertEquals(Assert.java:188)
	at Rough.Newmultiplelogin.DataDrivenFrameEx(Newmultiplelogin.java:46)
	at sun.reflect.NativeMethodAccessorImpl.invoke0(Native Method)
	at sun.reflect.NativeMethodAccessorImpl.invoke(Unknown Source)
	at sun.reflect.DelegatingMethodAccessorImpl.invoke(Unknown Source)
	at java.lang.reflect.Method.invoke(Unknown Source)
	at org.testng.internal.MethodInvocationHelper.invokeMethod(MethodInvocationHelper.java:85)
	at org.testng.internal.Invoker.invokeMethod(Invoker.java:639)
	at org.testng.internal.Invoker.invokeTestMethod(Invoker.java:816)
	at org.testng.internal.Invoker.invokeTestMethods(Invoker.java:1124)
	at org.testng.internal.TestMethodWorker.invokeTestMethods(TestMethodWorker.java:125)
	at org.testng.internal.TestMethodWorker.run(TestMethodWorker.java:108)
	at org.testng.TestRunner.privateRun(TestRunner.java:774)
	at org.testng.TestRunner.run(TestRunner.java:624)
	at org.testng.SuiteRunner.runTest(SuiteRunner.java:359)
	at org.testng.SuiteRunner.runSequentially(SuiteRunner.java:354)
	at org.testng.SuiteRunner.privateRun(SuiteRunner.java:312)
	at org.testng.SuiteRunner.run(SuiteRunner.java:261)
	at org.testng.SuiteRunnerWorker.runSuite(SuiteRunnerWorker.java:52)
	at org.testng.SuiteRunnerWorker.run(SuiteRunnerWorker.java:86)
	at org.testng.TestNG.runSuitesSequentially(TestNG.java:1215)
	at org.testng.TestNG.runSuitesLocally(TestNG.java:1140)
	at org.testng.TestNG.run(TestNG.java:1048)
	at org.testng.remote.RemoteTestNG.run(RemoteTestNG.java:112)
	at org.testng.remote.RemoteTestNG.initAndRun(RemoteTestNG.java:205)
	at org.testng.remote.RemoteTestNG.main(RemoteTestNG.java:176)
]]>
            </full-stacktrace>
          </exception> <!-- java.lang.AssertionError -->
          <reporter-output>
          </reporter-output>
        </test-method> <!-- DataDrivenFrameEx -->
        <test-method status="PASS" signature="closeapp()[pri:0, instance:Rough.Newmultiplelogin@7cdbc5d3]" name="closeapp" is-config="true" duration-ms="825" started-at="2019-07-09T15:31:28Z" finished-at="2019-07-09T15:31:29Z">
          <reporter-output>
          </reporter-output>
        </test-method> <!-- closeapp -->
        <test-method status="FAIL" signature="DataDrivenFrameEx(java.lang.String, java.lang.String)[pri:0, instance:Rough.Newmultiplelogin@7cdbc5d3]" name="DataDrivenFrameEx" duration-ms="12260" started-at="2019-07-09T15:31:29Z" data-provider="getData" finished-at="2019-07-09T15:31:41Z">
          <params>
            <param index="0">
              <value>
                <![CDATA[cccccc]]>
              </value>
            </param>
            <param index="1">
              <value>
                <![CDATA[eeeee]]>
              </value>
            </param>
          </params>
          <exception class="java.lang.AssertionError">
            <message>
              <![CDATA[expected [https://opensource-demo.orangehrmlive.com/index.php/auth/validateCredentials] but found [https://opensource-demo.orangehrmlive.com/index.php/dashboard]]]>
            </message>
            <full-stacktrace>
              <![CDATA[java.lang.AssertionError: expected [https://opensource-demo.orangehrmlive.com/index.php/auth/validateCredentials] but found [https://opensource-demo.orangehrmlive.com/index.php/dashboard]
	at org.testng.Assert.fail(Assert.java:94)
	at org.testng.Assert.failNotEquals(Assert.java:496)
	at org.testng.Assert.assertEquals(Assert.java:125)
	at org.testng.Assert.assertEquals(Assert.java:178)
	at org.testng.Assert.assertEquals(Assert.java:188)
	at Rough.Newmultiplelogin.DataDrivenFrameEx(Newmultiplelogin.java:46)
	at sun.reflect.NativeMethodAccessorImpl.invoke0(Native Method)
	at sun.reflect.NativeMethodAccessorImpl.invoke(Unknown Source)
	at sun.reflect.DelegatingMethodAccessorImpl.invoke(Unknown Source)
	at java.lang.reflect.Method.invoke(Unknown Source)
	at org.testng.internal.MethodInvocationHelper.invokeMethod(MethodInvocationHelper.java:85)
	at org.testng.internal.Invoker.invokeMethod(Invoker.java:639)
	at org.testng.internal.Invoker.invokeTestMethod(Invoker.java:816)
	at org.testng.internal.Invoker.invokeTestMethods(Invoker.java:1124)
	at org.testng.internal.TestMethodWorker.invokeTestMethods(TestMethodWorker.java:125)
	at org.testng.internal.TestMethodWorker.run(TestMethodWorker.java:108)
	at org.testng.TestRunner.privateRun(TestRunner.java:774)
	at org.testng.TestRunner.run(TestRunner.java:624)
	at org.testng.SuiteRunner.runTest(SuiteRunner.java:359)
	at org.testng.SuiteRunner.runSequentially(SuiteRunner.java:354)
	at org.testng.SuiteRunner.privateRun(SuiteRunner.java:312)
	at org.testng.SuiteRunner.run(SuiteRunner.java:261)
	at org.testng.SuiteRunnerWorker.runSuite(SuiteRunnerWorker.java:52)
	at org.testng.SuiteRunnerWorker.run(SuiteRunnerWorker.java:86)
	at org.testng.TestNG.runSuitesSequentially(TestNG.java:1215)
	at org.testng.TestNG.runSuitesLocally(TestNG.java:1140)
	at org.testng.TestNG.run(TestNG.java:1048)
	at org.testng.remote.RemoteTestNG.run(RemoteTestNG.java:112)
	at org.testng.remote.RemoteTestNG.initAndRun(RemoteTestNG.java:205)
	at org.testng.remote.RemoteTestNG.main(RemoteTestNG.java:176)
]]>
            </full-stacktrace>
          </exception> <!-- java.lang.AssertionError -->
          <reporter-output>
          </reporter-output>
        </test-method> <!-- DataDrivenFrameEx -->
        <test-method status="PASS" signature="closeapp()[pri:0, instance:Rough.Newmultiplelogin@7cdbc5d3]" name="closeapp" is-config="true" duration-ms="802" started-at="2019-07-09T15:31:41Z" finished-at="2019-07-09T15:31:42Z">
          <reporter-output>
          </reporter-output>
        </test-method> <!-- closeapp -->
      </class> <!-- Rough.Newmultiplelogin -->
    </test> <!-- Default test -->
  </suite> <!-- Default suite -->
</testng-results>
